<?xml version="1.0"?>
<robot name="wheel" xmlns:xacro="http://www.ros.org/wiki/xacro">
  
<!-- \\\\\\\\\\\\\\\\\\\\\\\\\\\\\\\\\\\ -->  
<!-- \\\ URDF file of a Single Wheel \\\ -->
<!-- \\\\\\\\\\\\\\\\\\\\\\\\\\\\\\\\\\\ -->
  
  <!-- Parameters -->
  <xacro:property name="wheel_radius" value="0.04" />   <!--[m]-->
  <xacro:property name="wheel_height" value="0.02" />   <!--[m]--> 
  <xacro:property name="wheel_mass" value="2.5" />      <!--[kg]-->
  
  <xacro:property name="base_x_origin_to_wheel_origin" value="0.25" />  <!--[m]-->
  <xacro:property name="base_y_origin_to_wheel_origin" value="0.3" />   <!--[m]-->
  <xacro:property name="base_z_origin_to_wheel_origin" value="0.0" />   <!--[m]-->
  
  <!-- Wheels Macro -->
  <xacro:macro name="wheel" params="fb lr parent translateX translateY flipY"> <!--fb : front, back ; lr: left, right -->
    
    <!-- // LINK // -->
    <link name="${fb}_${lr}_wheel">
      <!-- Visual -->
      <visual>
        <origin xyz="0 0 0" rpy="${flipY*M_PI/2} 0  0 " /> 
        <geometry>
          <cylinder length="${wheel_height}" radius="${wheel_radius}" />
        </geometry>
        <material name="Red">
          <color rgba="0.8 0.0 0.0 1.0"/>
        </material>
      </visual>

      <!-- Collision -->
      <collision>
        <origin xyz="0 0 0" rpy="${flipY*M_PI/2} 0 0 " />
        <geometry>
          <cylinder length="${wheel_height}" radius="${wheel_radius}" />
        </geometry>
      </collision>

      <!-- Inertial -->
      <inertial>
        <mass value="${wheel_mass}" />
        <origin xyz="0 0 0" />
				<inertia ixx="0.001" ixy="0.0" ixz="0.0"
               iyy="0.001" iyz="0.0" 
               izz="0.001" />
      </inertial>
    </link>

    <!-- Physic parameters for Gazebo -->
    <gazebo reference="${fb}_${lr}_wheel">
      <mu1 value="1.0"/>
      <mu2 value="1.0"/>
      <kp  value="10000000.0"/>
      <kd  value="1.0" />
      <fdir1 value="1 0 0"/>
      <material>Gazebo/Grey</material>
      <turnGravityOff>false</turnGravityOff>
    </gazebo>

    <!-- // JOINT // -->
    <joint name="${fb}_${lr}_wheel_joint" type="continuous">
      <parent link="${parent}"/>
      <child link="${fb}_${lr}_wheel"/>
      <origin xyz="${translateX * base_x_origin_to_wheel_origin} ${translateY * base_y_origin_to_wheel_origin} ${base_z_origin_to_wheel_origin}" rpy="0 0 0" /> 
      <axis xyz="0 1 0" rpy="0 0 0" />
      <limit effort="100" velocity="100"/>
      <joint_properties damping="0.0" friction="0.0"/>
    </joint>

    <!-- Transmission is important to link the joints and the controller -->
    <transmission name="${fb}_${lr}_wheel_joint_trans">
      <type>transmission_interface/SimpleTransmission</type>
      <joint name="${fb}_${lr}_wheel_joint" />

      <!-- Define Actuation type-->
      <actuator name="${fb}_${lr}_wheel_joint_motor">
        <hardwareInterface>EffortJointInterface</hardwareInterface>
        <mechanicalReduction>1</mechanicalReduction>
      </actuator>
    </transmission>
   
  </xacro:macro>
</robot>